<?xml version="1.0"?>
<robot xmlns:xacro="http://www.ros.org/wiki/xacro" >
    <xacro:include filename="inertial_macros.xacro" />

<!-- MATERIAL -->

    <material name="white">
        <color rgba="1 1 1 1" />
    </material>

    <material name="black">
        <color rgba="0 0 0 1"/>
    </material>

 <!-- BASE LINK -->
    <link name="base_link"> <!-- สร้าง link ชื่อ base_link  -->

    </link>


<!--chassis-->

    <link name="chassis"> <!-- สร้าง link ชื่อ chassis  -->
        <visual> 
            <origin xyz="0 0 0" rpy="0 0 0"/> <!-- กำหนด visual ของ link chassis และตั้งค่าพิกัด (x, y, z) และแกนหมุน -->
            <geometry>
                <mesh filename="file://$(find articubot_one)/description/robolab2/blend/body.dae" scale="1 1 1"/>
            </geometry>
            <material name="white"/> <!-- ดึงข้อมูลค่าสีจาก material ชื่อ white -->
        </visual>
        <collision> 
            <origin xyz="0 0 0" rpy="0 0 0"/> <!-- กำหนด collision ของ link chassis และตั้งค่าพิกัด (x, y, z) และแกนหมุน -->
            <geometry>
                <mesh filename="file://$(find articubot_one)/description/robolab2/blend/body.dae" scale="1 1 1"/>
            </geometry>
        </collision>
        <xacro:inertial_box mass="1" x="0.375" y="0.75" z="0.525"> <!-- กำหนด inertial_box ค่ามวล และพิกัดของ inertial -->
            <origin xyz="0 0.02 0.25" rpy="0 0 0"/> <!-- กำหนด inertial_box ของ link chassis และตั้งค่าพิกัด (x, y, z) และแกนหมุน -->
        </xacro:inertial_box>
    </link>
    <gazebo reference="chassis">
        <material>Gazebo/White</material>
    </gazebo>


    <joint name="chassis_joint" type="fixed"> <!-- สร้าง joint ชื่อ chassis_joint แบบ fixed  -->
        <parent link="base_link"/> <!-- สร้าง joint_link หลัก ชื่อ base_link -->
        <child link="chassis"/> <!-- สร้าง joint_link ย่อย ชื่อ chassis -->
        <origin xyz="0 0 0"/> <!-- กำหนดตั้งค่าพิกัด (x, y, z) ของ joint -->
    </joint>

    <!-- BASE_FOOTPRINT LINK -->

    <joint name="base_footprint_joint" type="fixed">
        <parent link="base_link"/>
        <child link="base_footprint"/>
        <origin xyz="0 0 0" rpy="0 0 0"/>
    </joint>

    <link name="base_footprint">
    </link>
<!--LEFT-WHEEl-->

    <joint name="left_wheel_joint" type="continuous"> <!-- สร้าง joint ชื่อ left_wheel_joint แบบ continuous  -->
        <parent link="base_link"/> <!-- สร้าง joint_link หลัก ชื่อ base_link -->
        <child link="left_wheel"/> <!-- สร้าง joint_link ย่อย ชื่อ left_wheel -->
        <origin xyz="0.2 0.25 0" rpy="0 ${pi/2} 0"/> <!-- กำหนดตั้งค่าพิกัด (x, y, z) และการหันหน้าของ joint -->
        <axis xyz="0 0 1"/> <!-- กำหนดแกนหมุนของ joint -->
    </joint>
    <link name="left_wheel"> <!-- สร้าง link ชื่อ left_wheel  -->
        <visual>
            <geometry>
                <cylinder length="0.12" radius="0.12" /> <!-- สร้างทรงกระบอก visual และกำหนดความยาวและรัศมี -->
            </geometry>
            <material name="black"/> <!-- ดึงข้อมูลค่าสีจาก material ชื่อ blue -->
        </visual>
        <collision> 
            <geometry>
                <cylinder length="0.12" radius="0.12" />  <!-- สร้างกล่อง collision และกำหนดขนาด -->
            </geometry>
        </collision>
        <xacro:inertial_cylinder mass="0.05" length="0.12" radius="0.12"> <!-- กำหนด inertial_cylinder ค่ามวล ความยาวและรัศมี -->
            <origin xyz="0 0 0" rpy="0 0 0"/> <!-- กำหนด inertial_cylinder ของ link left_wheel และตั้งค่าพิกัด (x, y, z) และแกนหมุน -->
        </xacro:inertial_cylinder>
    </link>
    <gazebo reference="left_wheel">
        <material>Gazebo/Black</material>
        <!-- <mu1 value="0.001"/>
        <mu2 value="0.001"/> -->
    </gazebo>

<!--FRIGHT-WHEEl-->

        <joint name="fright_wheel_joint" type="fixed"> <!-- สร้าง joint ชื่อ right_wheel_joint แบบ continuous  -->
        <parent link="base_link"/> <!-- สร้าง joint_link หลัก ชื่อ base_link -->
        <child link="fright_wheel"/> <!-- สร้าง joint_link ย่อย ชื่อ right_wheel -->
        <origin xyz="-0.13 -0.2 0" rpy="0 -${pi/2} 0"/> <!-- กำหนดตั้งค่าพิกัด (x, y, z) และการหันหน้าของ joint -->
        <axis xyz="0 0 -1"/> <!-- กำหนดแกนหมุนของ joint -->
    </joint>
    <link name="fright_wheel"> <!-- สร้าง link ชื่อ right_wheel  -->
        <visual>
            <geometry>
                <cylinder length="0.12" radius="0.12" /> <!-- สร้างทรงกระบอก visual และกำหนดความยาวและรัศมี -->
            </geometry>
            <material name="black"/> <!-- ดึงข้อมูลค่าสีจาก material ชื่อ blue -->
        </visual>
        <collision> 
            <geometry>
                <cylinder length="0.12" radius="0.12" />  <!-- สร้างกล่อง collision และกำหนดขนาด -->
            </geometry>
        </collision>
        <xacro:inertial_cylinder mass="0.05" length="0.12" radius="0.12"> <!-- กำหนด inertial_cylinder ค่ามวล ความยาวและรัศมี -->
            <origin xyz="0 0 0" rpy="0 0 0"/> <!-- กำหนด inertial_cylinder ของ link right_wheel และตั้งค่าพิกัด (x, y, z) และแกนหมุน -->
        </xacro:inertial_cylinder>
    </link>
    <gazebo reference="fright_wheel">
        <material>Gazebo/Black</material>
        <mu1 value="0.001"/>
        <mu2 value="0.001"/>
    </gazebo>
<!--F-LEFT-WHEEl-->

    <joint name="fleft_wheel_joint" type="fixed"> <!-- สร้าง joint ชื่อ left_wheel_joint แบบ continuous  -->
        <parent link="base_link"/> <!-- สร้าง joint_link หลัก ชื่อ base_link -->
        <child link="fleft_wheel"/> <!-- สร้าง joint_link ย่อย ชื่อ left_wheel -->
        <origin xyz="0.13 -0.2 0" rpy="0 ${pi/2} 0"/> <!-- กำหนดตั้งค่าพิกัด (x, y, z) และการหันหน้าของ joint -->
        <axis xyz="0 0 1"/> <!-- กำหนดแกนหมุนของ joint -->
    </joint>
    <link name="fleft_wheel"> <!-- สร้าง link ชื่อ left_wheel  -->
        <visual>
            <geometry>
                <cylinder length="0.12" radius="0.12" /> <!-- สร้างทรงกระบอก visual และกำหนดความยาวและรัศมี -->
            </geometry>
            <material name="black"/> <!-- ดึงข้อมูลค่าสีจาก material ชื่อ blue -->
        </visual>
        <collision> 
            <geometry>
                <cylinder length="0.12" radius="0.12" />  <!-- สร้างกล่อง collision และกำหนดขนาด -->
            </geometry>
        </collision>
        <xacro:inertial_cylinder mass="0.05" length="0.12" radius="0.12"> <!-- กำหนด inertial_cylinder ค่ามวล ความยาวและรัศมี -->
            <origin xyz="0 0 0" rpy="0 0 0"/> <!-- กำหนด inertial_cylinder ของ link left_wheel และตั้งค่าพิกัด (x, y, z) และแกนหมุน -->
        </xacro:inertial_cylinder>
    </link>
    <gazebo reference="fleft_wheel">
        <material>Gazebo/Black</material>
        <mu1 value="0.001"/>
        <mu2 value="0.001"/>
    </gazebo>

<!--RIGHT-WHEEl-->

        <joint name="right_wheel_joint" type="continuous"> <!-- สร้าง joint ชื่อ right_wheel_joint แบบ continuous  -->
        <parent link="base_link"/> <!-- สร้าง joint_link หลัก ชื่อ base_link -->
        <child link="right_wheel"/> <!-- สร้าง joint_link ย่อย ชื่อ right_wheel -->
        <origin xyz="-0.2 0.25 0" rpy="0 -${pi/2} 0"/> <!-- กำหนดตั้งค่าพิกัด (x, y, z) และการหันหน้าของ joint -->
        <axis xyz="0 0 -1"/> <!-- กำหนดแกนหมุนของ joint -->
    </joint>
    <link name="right_wheel"> <!-- สร้าง link ชื่อ right_wheel  -->
        <visual>
            <geometry>
                <cylinder length="0.12" radius="0.12" /> <!-- สร้างทรงกระบอก visual และกำหนดความยาวและรัศมี -->
            </geometry>
            <material name="black"/> <!-- ดึงข้อมูลค่าสีจาก material ชื่อ blue -->
        </visual>
        <collision> 
            <geometry>
                <cylinder length="0.12" radius="0.12" />  <!-- สร้างกล่อง collision และกำหนดขนาด -->
            </geometry>
        </collision>
        <xacro:inertial_cylinder mass="0.05" length="0.12" radius="0.12"> <!-- กำหนด inertial_cylinder ค่ามวล ความยาวและรัศมี -->
            <origin xyz="0 0 0" rpy="0 0 0"/> <!-- กำหนด inertial_cylinder ของ link right_wheel และตั้งค่าพิกัด (x, y, z) และแกนหมุน -->
        </xacro:inertial_cylinder>
    </link>
    <gazebo reference="right_wheel">
        <material>Gazebo/Black</material>
        <!-- <mu1 value="0.001"/>
        <mu2 value="0.001"/> -->
    </gazebo>

<!--LEFT-CON-->

    <joint name="left_con_joint" type="revolute"> <!-- สร้าง joint ชื่อ left_wheel_joint แบบ continuous  -->
        <parent link="chassis"/> <!-- สร้าง joint_link หลัก ชื่อ base_link -->
        <child link="left_con"/> <!-- สร้าง joint_link ย่อย ชื่อ left_wheel -->
        <origin xyz="0.2 0.03753 0.0375" rpy="0 0 0"/> <!-- กำหนดตั้งค่าพิกัด (x, y, z) และการหันหน้าของ joint -->
        <limit effort="1000.0" lower="-0.225" upper="1.57" velocity="0.5"/>
        <axis xyz="-1 0 0"/> <!-- กำหนดแกนหมุนของ joint -->
    </joint>
    <link name="left_con"> <!-- สร้าง link ชื่อ left_wheel  -->
        <visual>
            <origin xyz="0 -0.231 0" rpy="0 0 0"/>
            <geometry>
                <box size="0.015 0.537 0.075"/> <!-- สร้างกล่อง visual และกำหนดขนาด --> 
            </geometry>
            <material name="black"/> <!-- ดึงข้อมูลค่าสีจาก material ชื่อ blue -->
        </visual>
        <collision> 
            <origin xyz="0 -0.231 0" rpy="0 0 0"/>
            <geometry>
                <box size="0.015 0.537 0.075"/>  <!-- สร้างกล่อง collision และกำหนดขนาด -->
            </geometry>
        </collision>
        <xacro:inertial_box mass="0.1" x="0.001" y="0.537" z="0.075"> <!-- กำหนด inertial_cylinder ค่ามวล ความยาวและรัศมี -->
            <origin xyz="0.205 0.03753 0.0375" rpy="0 0 0"/> <!-- กำหนด inertial_cylinder ของ link left_wheel และตั้งค่าพิกัด (x, y, z) และแกนหมุน -->
        </xacro:inertial_box>
    </link>
    <gazebo reference="left_con">
        <material>Gazebo/Black</material>
        <!-- <mu1 value="0.001"/>
        <mu2 value="0.001"/> -->
    </gazebo>

<!--fake joint-->

    <joint name="fake_con_joint" type="continuous"> <!-- สร้าง joint ชื่อ left_wheel_joint แบบ continuous  -->
        <parent link="chassis"/> <!-- สร้าง joint_link หลัก ชื่อ base_link -->
        <child link="fake_con"/> <!-- สร้าง joint_link ย่อย ชื่อ left_wheel -->
        <origin xyz="-0.2 0.03753 0.0375" rpy="0 0 0"/> <!-- กำหนดตั้งค่าพิกัด (x, y, z) และการหันหน้าของ joint -->
        <limit effort="1000.0" lower="-0.225" upper="1.57" velocity="0.5"/>
        <axis xyz="-1 0 0"/> <!-- กำหนดแกนหมุนของ joint -->
    </joint>
    <link name="fake_con"> <!-- สร้าง link ชื่อ left_wheel  -->
        <visual>
            <geometry>
            </geometry>
        </visual>
        <collision> 
        </collision>
        <xacro:inertial_box mass="0.00001" x="0.001" y="0.001" z="0.001"> <!-- กำหนด inertial_cylinder ค่ามวล ความยาวและรัศมี -->
            <origin xyz="-0.205 0.03753 0.0375" rpy="0 0 0"/> <!-- กำหนด inertial_cylinder ของ link left_wheel และตั้งค่าพิกัด (x, y, z) และแกนหมุน -->
        </xacro:inertial_box>
    </link>
    <gazebo reference="fake_con">
        <material>Gazebo/Black</material>
        <!-- <mu1 value="0.001"/>
        <mu2 value="0.001"/> -->
    </gazebo>

<!--RIGHT-CON-->

    <joint name="right_con_joint" type="fixed"> <!-- สร้าง joint ชื่อ left_wheel_joint แบบ continuous  -->
        <parent link="left_con"/> <!-- สร้าง joint_link หลัก ชื่อ base_link -->
        <child link="right_con"/> <!-- สร้าง joint_link ย่อย ชื่อ left_wheel -->
        <limit effort="1000.0" lower="0.0" upper="1.57" velocity="0.5"/>
        <origin xyz="-0.4 0 0" rpy="0 0 0"/> <!-- กำหนดตั้งค่าพิกัด (x, y, z) และการหันหน้าของ joint -->
        <axis xyz="-1 0 0"/> <!-- กำหนดแกนหมุนของ joint -->
    </joint>
    <link name="right_con"> <!-- สร้าง link ชื่อ left_wheel  -->
        <visual>
            <origin xyz="0 -0.231 0" rpy="0 0 0"/>
            <geometry>
                <box size="0.015 0.537 0.075"/> <!-- สร้างกล่อง visual และกำหนดขนาด --> 
            </geometry>
            <material name="black"/> <!-- ดึงข้อมูลค่าสีจาก material ชื่อ blue -->
        </visual>
        <collision> 
            <origin xyz="0 -0.231 0" rpy="0 0 0"/>
            <geometry>
                <box size="0.015 0.537 0.075"/>  <!-- สร้างกล่อง collision และกำหนดขนาด -->
            </geometry>
        </collision>
        <xacro:inertial_box mass="0.1" x="0.015" y="0.537" z="0.075"> <!-- กำหนด inertial_cylinder ค่ามวล ความยาวและรัศมี -->
            <origin xyz="-0.205 0.03753 0.0375" rpy="0 0 0"/> <!-- กำหนด inertial_cylinder ของ link left_wheel และตั้งค่าพิกัด (x, y, z) และแกนหมุน -->
        </xacro:inertial_box>
    </link>
    <gazebo reference="right_con">
        <material>Gazebo/Black</material>
        <!-- <mu1 value="0.001"/>
        <mu2 value="0.001"/> -->
    </gazebo>

<!--ARM-->

    <joint name="arm_joint" type="revolute"> <!-- สร้าง joint ชื่อ left_wheel_joint แบบ continuous  -->
        <parent link="left_con"/> <!-- สร้าง joint_link หลัก ชื่อ base_link -->
        <child link="arm"/> <!-- สร้าง joint_link ย่อย ชื่อ left_wheel -->
        <limit effort="1000.0" lower="0.0" upper="1.57" velocity="0.5"/>
        <origin xyz="-0.0125 -0.46265 0" rpy="0 0 0"/> <!-- กำหนดตั้งค่าพิกัด (x, y, z) และการหันหน้าของ joint -->
        <axis xyz="-1 0 0"/> <!-- กำหนดแกนหมุนของ joint -->
    </joint>
    <link name="arm"> <!-- สร้าง link ชื่อ left_wheel  -->
        <visual>
            <origin xyz="-0.1875 -0.147 -0.0375" rpy="0 0 0"/>
            <geometry>
                <mesh filename="file://$(find articubot_one)/description/robolab2/blend/arm.dae" scale="1 1 1"/>
            </geometry>
            <material name="black"/> <!-- ดึงข้อมูลค่าสีจาก material ชื่อ blue -->
        </visual>
        <collision> 
            <origin xyz="-0.1875 -0.147 -0.0375" rpy="0 0 0"/>
            <geometry>
                <mesh filename="file://$(find articubot_one)/description/robolab2/blend/arm.dae" scale="1 1 1"/>
            </geometry>
        </collision>
        <xacro:inertial_box mass="0.1" x="0.375" y="0.294" z="0.122"> <!-- กำหนด inertial_cylinder ค่ามวล ความยาวและรัศมี -->
            <origin xyz="-0.18 -0.19 0" rpy="0 0 0"/> <!-- กำหนด inertial_cylinder ของ link left_wheel และตั้งค่าพิกัด (x, y, z) และแกนหมุน -->
        </xacro:inertial_box>
    </link>
    <gazebo reference="arm">
        <material>Gazebo/White</material>
        <!-- <mu1 value="0.001"/>
        <mu2 value="0.001"/> -->
    </gazebo>

</robot>